Traceback (most recent call last):
  File "/Users/edoardo/anaconda3/lib/python3.11/site-packages/wandb/sdk/wandb_config.py", line 165, in __getattr__
    return self.__getitem__(key)
           ^^^^^^^^^^^^^^^^^^^^^
  File "/Users/edoardo/anaconda3/lib/python3.11/site-packages/wandb/sdk/wandb_config.py", line 130, in __getitem__
    return self._items[key]
           ~~~~~~~~~~~^^^^^
KeyError: 'NUM_EPOCHS'

The above exception was the direct cause of the following exception:

Traceback (most recent call last):
  File "/Users/edoardo/Desktop/Thesis/code/Tomography/Draft_model/src_c/train_c.py", line 87, in main
    max_epochs=config.NUM_EPOCHS,
               ^^^^^^^^^^^^^^^^^
  File "/Users/edoardo/anaconda3/lib/python3.11/site-packages/wandb/sdk/wandb_config.py", line 167, in __getattr__
    raise AttributeError(
AttributeError: <class 'wandb.sdk.wandb_config.Config'> object has no attribute 'NUM_EPOCHS'
