Traceback (most recent call last):
  File "/Users/edoardo/anaconda3/lib/python3.11/site-packages/wandb/sdk/wandb_config.py", line 165, in __getattr__
    return self.__getitem__(key)
           ^^^^^^^^^^^^^^^^^^^^^
  File "/Users/edoardo/anaconda3/lib/python3.11/site-packages/wandb/sdk/wandb_config.py", line 130, in __getitem__
    return self._items[key]
           ~~~~~~~~~~~^^^^^
KeyError: 'LEARNING_RATE'

The above exception was the direct cause of the following exception:

Traceback (most recent call last):
  File "/Users/edoardo/Desktop/Thesis/code/Tomography/Draft_model/src_c/train_c.py", line 58, in main
    learning_rate=config.LEARNING_RATE,
                  ^^^^^^^^^^^^^^^^^^^^
  File "/Users/edoardo/anaconda3/lib/python3.11/site-packages/wandb/sdk/wandb_config.py", line 167, in __getattr__
    raise AttributeError(
AttributeError: <class 'wandb.sdk.wandb_config.Config'> object has no attribute 'LEARNING_RATE'
